2020-05-14 00:36:27,995 - teradata.udaexec - INFO - Initializing UdaExec...
2020-05-14 00:36:27,995 - teradata.udaexec - INFO - Reading config files: ['/etc/udaexec.ini: Not Found', '/home/kamil/udaexec.ini: Not Found', '/home/kamil/Pulpit/Teradata/Repo/Teradata-statistics/udaexec.ini: Not Found']
2020-05-14 00:36:27,995 - teradata.udaexec - INFO - Found run number file: "/home/kamil/Pulpit/Teradata/Repo/Teradata-statistics/.runNumber"
2020-05-14 00:36:27,995 - teradata.udaexec - INFO - Cleaning up log files older than 90 days.
2020-05-14 00:36:27,995 - teradata.udaexec - INFO - Removed 0 log files.
2020-05-14 00:36:28,011 - teradata.udaexec - INFO - Checkpoint file not found: /home/kamil/Pulpit/Teradata/Repo/Teradata-statistics/SQL shell.checkpoint
2020-05-14 00:36:28,013 - teradata.udaexec - INFO - No previous checkpoint found, executing from beginning...
2020-05-14 00:36:28,013 - teradata.udaexec - INFO - Execution Details:
/********************************************************************************
 * Application Name: SQL shell
 *          Version: 1.0
 *       Run Number: 20200514003627-16
 *             Host: kamil-MS-7A34
 *         Platform: Linux-4.15.0-91-generic-x86_64-with-Ubuntu-18.04-bionic
 *          OS User: kamil
 *   Python Version: 3.6.9
 *  Python Compiler: GCC 8.4.0
 *     Python Build: ('default', 'Apr 18 2020 01:56:04')
 *  UdaExec Version: 15.10.0.21
 *     Program Name: script.py
 *      Working Dir: /home/kamil/Pulpit/Teradata/Repo/Teradata-statistics
 *      Git Version: git version 2.17.1
 *     Git Revision: 181db07
 *        Git Dirty: True [ M libs/analysis/daily_usage.py, M libs/samples.sql, M libs/utils.py, M script.py, M settings.json,?? .runNumber,?? logs/,?? sqls/]
 *          Log Dir: /home/kamil/Pulpit/Teradata/Repo/Teradata-statistics/logs
 *         Log File: /home/kamil/Pulpit/Teradata/Repo/Teradata-statistics/logs/SQL shell.20200514003627-16.log
 *     Config Files: ['/etc/udaexec.ini: Not Found', '/home/kamil/udaexec.ini: Not Found', '/home/kamil/Pulpit/Teradata/Repo/Teradata-statistics/udaexec.ini: Not Found']
 *      Query Bands: ApplicationName=SQL shell;Version=1.0;JobID=20200514003627-16;ClientUser=kamil;Production=False;udaAppLogFile=/home/kamil/Pulpit/Teradata/Repo/Teradata-statistics/logs/SQL shell.20200514003627-16.log;gitRevision=181db07;gitDirty=True;UtilityName=PyTd;UtilityVersion=15.10.0.21
********************************************************************************/
2020-05-14 00:36:28,015 - teradata.udaexec - INFO - Creating connection: {'method': 'odbc', 'system': '192.168.0.110', 'username': 'dbc', 'password': 'XXXXXX'}
2020-05-14 00:36:28,015 - teradata.tdodbc - INFO - Loading ODBC Library: /opt/teradata/client/ODBC_64/lib/libodbc.so
2020-05-14 00:36:28,020 - teradata.tdodbc - INFO - Available drivers: Teradata Database ODBC Driver 16.20, 
2020-05-14 00:36:28,163 - teradata.udaexec - INFO - Connection successful. Duration: 0.148 seconds. Details: {'method': 'odbc', 'system': '192.168.0.110', 'username': 'dbc', 'password': 'XXXXXX'}
2020-05-14 00:36:28,168 - teradata.udaexec - INFO - Query Successful. Duration: 0.004 seconds, Rows: 0, Query: SELECT DISTINCT calendar_date FROM Sys_Calendar.Calendar AS CALENDAR
LEFT OUTER JOIN 
(SELECT * FROM TDSP_ANALYSIS.daily_usage) AS MEASURES 
ON calendar_date = measure_date
WHERE calendar_date<=cast('2020-04-14' as DATE) 
AND calendar_date>=cast('2020-05-14' as DATE)
AND
(complete=0 OR complete IS NULL);
2020-05-14 00:36:28,188 - teradata.udaexec - ERROR - Uncaught exception
Traceback (most recent call last):
  File "/home/kamil/Pulpit/Teradata/praca/pythonowe/virtualenv/teradata/lib/python3.6/site-packages/pandas/core/indexes/base.py", line 4404, in get_value
    return self._engine.get_value(s, k, tz=getattr(series.dtype, "tz", None))
  File "pandas/_libs/index.pyx", line 80, in pandas._libs.index.IndexEngine.get_value
  File "pandas/_libs/index.pyx", line 90, in pandas._libs.index.IndexEngine.get_value
  File "pandas/_libs/index.pyx", line 138, in pandas._libs.index.IndexEngine.get_loc
  File "pandas/_libs/hashtable_class_helper.pxi", line 1619, in pandas._libs.hashtable.PyObjectHashTable.get_item
  File "pandas/_libs/hashtable_class_helper.pxi", line 1627, in pandas._libs.hashtable.PyObjectHashTable.get_item
KeyError: 0

During handling of the above exception, another exception occurred:

Traceback (most recent call last):
  File "script.py", line 70, in <module>
    new_one.days_missing(table_name, runtime_settings["begin"], runtime_settings["end"])
  File "/home/kamil/Pulpit/Teradata/Repo/Teradata-statistics/libs/analysis/daily_usage.py", line 34, in days_missing
    print(days["calendar_date"][0])
  File "/home/kamil/Pulpit/Teradata/praca/pythonowe/virtualenv/teradata/lib/python3.6/site-packages/pandas/core/series.py", line 871, in __getitem__
    result = self.index.get_value(self, key)
  File "/home/kamil/Pulpit/Teradata/praca/pythonowe/virtualenv/teradata/lib/python3.6/site-packages/pandas/core/indexes/base.py", line 4410, in get_value
    return libindex.get_value_at(s, key)
  File "pandas/_libs/index.pyx", line 44, in pandas._libs.index.get_value_at
  File "pandas/_libs/index.pyx", line 45, in pandas._libs.index.get_value_at
  File "pandas/_libs/util.pxd", line 98, in pandas._libs.util.get_value_at
  File "pandas/_libs/util.pxd", line 89, in pandas._libs.util.validate_indexer
IndexError: index out of bounds
2020-05-14 00:36:28,247 - teradata.udaexec - INFO - UdaExec exiting.
