2020-05-14 02:13:24,274 - teradata.udaexec - INFO - Initializing UdaExec...
2020-05-14 02:13:24,275 - teradata.udaexec - INFO - Reading config files: ['/etc/udaexec.ini: Not Found', '/home/kamil/udaexec.ini: Not Found', '/home/kamil/Pulpit/Teradata/Repo/Teradata-statistics/udaexec.ini: Not Found']
2020-05-14 02:13:24,275 - teradata.udaexec - INFO - Found run number file: "/home/kamil/Pulpit/Teradata/Repo/Teradata-statistics/.runNumber"
2020-05-14 02:13:24,275 - teradata.udaexec - INFO - Cleaning up log files older than 90 days.
2020-05-14 02:13:24,275 - teradata.udaexec - INFO - Removed 0 log files.
2020-05-14 02:13:24,291 - teradata.udaexec - INFO - Checkpoint file not found: /home/kamil/Pulpit/Teradata/Repo/Teradata-statistics/SQL shell.checkpoint
2020-05-14 02:13:24,293 - teradata.udaexec - INFO - No previous checkpoint found, executing from beginning...
2020-05-14 02:13:24,293 - teradata.udaexec - INFO - Execution Details:
/********************************************************************************
 * Application Name: SQL shell
 *          Version: 1.0
 *       Run Number: 20200514021324-29
 *             Host: kamil-MS-7A34
 *         Platform: Linux-4.15.0-91-generic-x86_64-with-Ubuntu-18.04-bionic
 *          OS User: kamil
 *   Python Version: 3.6.9
 *  Python Compiler: GCC 8.4.0
 *     Python Build: ('default', 'Apr 18 2020 01:56:04')
 *  UdaExec Version: 15.10.0.21
 *     Program Name: script.py
 *      Working Dir: /home/kamil/Pulpit/Teradata/Repo/Teradata-statistics
 *      Git Version: git version 2.17.1
 *     Git Revision: 181db07
 *        Git Dirty: True [ M libs/analysis/daily_usage.py, M libs/init_db.sql, M libs/samples.sql, M libs/utils.py, M script.py, M settings.json,?? .runNumber,?? logs/,?? sqls/]
 *          Log Dir: /home/kamil/Pulpit/Teradata/Repo/Teradata-statistics/logs
 *         Log File: /home/kamil/Pulpit/Teradata/Repo/Teradata-statistics/logs/SQL shell.20200514021324-29.log
 *     Config Files: ['/etc/udaexec.ini: Not Found', '/home/kamil/udaexec.ini: Not Found', '/home/kamil/Pulpit/Teradata/Repo/Teradata-statistics/udaexec.ini: Not Found']
 *      Query Bands: ApplicationName=SQL shell;Version=1.0;JobID=20200514021324-29;ClientUser=kamil;Production=False;udaAppLogFile=/home/kamil/Pulpit/Teradata/Repo/Teradata-statistics/logs/SQL shell.20200514021324-29.log;gitRevision=181db07;gitDirty=True;UtilityName=PyTd;UtilityVersion=15.10.0.21
********************************************************************************/
2020-05-14 02:13:24,295 - teradata.udaexec - INFO - Creating connection: {'method': 'odbc', 'system': '192.168.0.110', 'username': 'dbc', 'password': 'XXXXXX'}
2020-05-14 02:13:24,295 - teradata.tdodbc - INFO - Loading ODBC Library: /opt/teradata/client/ODBC_64/lib/libodbc.so
2020-05-14 02:13:24,299 - teradata.tdodbc - INFO - Available drivers: Teradata Database ODBC Driver 16.20, 
2020-05-14 02:13:24,448 - teradata.udaexec - INFO - Connection successful. Duration: 0.153 seconds. Details: {'method': 'odbc', 'system': '192.168.0.110', 'username': 'dbc', 'password': 'XXXXXX'}
2020-05-14 02:13:24,459 - teradata.udaexec - INFO - Query Successful. Duration: 0.010 seconds, Rows: 8, Query: SELECT TableName FROM DBC.TablesV WHERE TableKind = 'T' AND DataBaseName='movies'
2020-05-14 02:13:24,476 - teradata.udaexec - ERROR - Uncaught exception
Traceback (most recent call last):
  File "script.py", line 75, in <module>
    libs.utils.check_table_name(session, table_name)
  File "/home/kamil/Pulpit/Teradata/Repo/Teradata-statistics/libs/utils.py", line 111, in check_table_name
    raise Exception("Cannot find table: " + table)
Exception: Cannot find table: movies.xd
2020-05-14 02:13:24,482 - teradata.udaexec - INFO - UdaExec exiting.
