2020-05-13 23:09:48,711 - teradata.udaexec - INFO - Initializing UdaExec...
2020-05-13 23:09:48,711 - teradata.udaexec - INFO - Reading config files: ['/etc/udaexec.ini: Not Found', '/home/kamil/udaexec.ini: Not Found', '/home/kamil/Pulpit/Teradata/Repo/Teradata-statistics/udaexec.ini: Not Found']
2020-05-13 23:09:48,711 - teradata.udaexec - INFO - Found run number file: "/home/kamil/Pulpit/Teradata/Repo/Teradata-statistics/.runNumber"
2020-05-13 23:09:48,711 - teradata.udaexec - INFO - Cleaning up log files older than 90 days.
2020-05-13 23:09:48,711 - teradata.udaexec - INFO - Removed 0 log files.
2020-05-13 23:09:48,722 - teradata.udaexec - INFO - Checkpoint file not found: /home/kamil/Pulpit/Teradata/Repo/Teradata-statistics/SQL shell.checkpoint
2020-05-13 23:09:48,723 - teradata.udaexec - INFO - No previous checkpoint found, executing from beginning...
2020-05-13 23:09:48,723 - teradata.udaexec - INFO - Execution Details:
/********************************************************************************
 * Application Name: SQL shell
 *          Version: 1.0
 *       Run Number: 20200513230948-4
 *             Host: kamil-MS-7A34
 *         Platform: Linux-4.15.0-91-generic-x86_64-with-Ubuntu-18.04-bionic
 *          OS User: kamil
 *   Python Version: 3.6.9
 *  Python Compiler: GCC 8.4.0
 *     Python Build: ('default', 'Apr 18 2020 01:56:04')
 *  UdaExec Version: 15.10.0.21
 *     Program Name: script.py
 *      Working Dir: /home/kamil/Pulpit/Teradata/Repo/Teradata-statistics
 *      Git Version: git version 2.17.1
 *     Git Revision: 181db07
 *        Git Dirty: True [ M libs/analysis/daily_usage.py, M libs/utils.py, M script.py, M settings.json,?? .runNumber,?? logs/]
 *          Log Dir: /home/kamil/Pulpit/Teradata/Repo/Teradata-statistics/logs
 *         Log File: /home/kamil/Pulpit/Teradata/Repo/Teradata-statistics/logs/SQL shell.20200513230948-4.log
 *     Config Files: ['/etc/udaexec.ini: Not Found', '/home/kamil/udaexec.ini: Not Found', '/home/kamil/Pulpit/Teradata/Repo/Teradata-statistics/udaexec.ini: Not Found']
 *      Query Bands: ApplicationName=SQL shell;Version=1.0;JobID=20200513230948-4;ClientUser=kamil;Production=False;udaAppLogFile=/home/kamil/Pulpit/Teradata/Repo/Teradata-statistics/logs/SQL shell.20200513230948-4.log;gitRevision=181db07;gitDirty=True;UtilityName=PyTd;UtilityVersion=15.10.0.21
********************************************************************************/
2020-05-13 23:09:48,725 - teradata.udaexec - INFO - Creating connection: {'method': 'odbc', 'system': '192.168.0.110', 'username': 'dbc', 'password': 'XXXXXX'}
2020-05-13 23:09:48,725 - teradata.tdodbc - INFO - Loading ODBC Library: /opt/teradata/client/ODBC_64/lib/libodbc.so
2020-05-13 23:09:48,732 - teradata.tdodbc - INFO - Available drivers: Teradata Database ODBC Driver 16.20, 
2020-05-13 23:09:48,890 - teradata.udaexec - INFO - Connection successful. Duration: 0.165 seconds. Details: {'method': 'odbc', 'system': '192.168.0.110', 'username': 'dbc', 'password': 'XXXXXX'}
2020-05-13 23:09:48,903 - teradata.udaexec - ERROR - Uncaught exception
Traceback (most recent call last):
  File "script.py", line 62, in <module>
    new_one = libs.utils.analysis_mapper(runtime_settings["analysis"][an])
  File "/home/kamil/Pulpit/Teradata/Repo/Teradata-statistics/libs/utils.py", line 95, in analysis_mapper
    raise Exception("Unknown analysis " + name)
TypeError: must be str, not list
2020-05-13 23:09:48,909 - teradata.udaexec - INFO - UdaExec exiting.
